<?xml version="1.0" encoding="UTF-8"?>
<!-- Generated by org.testng.reporters.JUnitReportReporter -->
<testsuite hostname="INLEN8520046048" failures="0" tests="1" name="com.testng.ExceptionTestNG" time="0.808" errors="1" timestamp="2023-08-24T09:47:58 IST" skipped="0">
  <testcase classname="com.testng.ExceptionTestNG" name="test1" time="0.808">
    <error message="
Method ExceptionTestNG.test1()[pri:0, instance:com.testng.ExceptionTestNG@48bb62] should have thrown an exception of type class org.openqa.selenium.NoSuchElementException" type="org.testng.TestException">
      <![CDATA[org.testng.TestException: 
Method ExceptionTestNG.test1()[pri:0, instance:com.testng.ExceptionTestNG@48bb62] should have thrown an exception of type class org.openqa.selenium.NoSuchElementException
at org.testng.internal.invokers.ExpectedExceptionsHolder.noException(ExpectedExceptionsHolder.java:81)
at org.testng.internal.invokers.TestInvoker.considerExceptions(TestInvoker.java:860)
at org.testng.internal.invokers.TestInvoker.invokeMethod(TestInvoker.java:718)
at org.testng.internal.invokers.TestInvoker.invokeTestMethod(TestInvoker.java:227)
at org.testng.internal.invokers.MethodRunner.runInSequence(MethodRunner.java:50)
at org.testng.internal.invokers.TestInvoker$MethodInvocationAgent.invoke(TestInvoker.java:957)
at org.testng.internal.invokers.TestInvoker.invokeTestMethods(TestInvoker.java:200)
at org.testng.internal.invokers.TestMethodWorker.invokeTestMethods(TestMethodWorker.java:148)
at org.testng.internal.invokers.TestMethodWorker.run(TestMethodWorker.java:128)
at java.base/java.util.ArrayList.forEach(ArrayList.java:1511)
at org.testng.TestRunner.privateRun(TestRunner.java:848)
at org.testng.TestRunner.run(TestRunner.java:621)
at org.testng.SuiteRunner.runTest(SuiteRunner.java:443)
at org.testng.SuiteRunner.runSequentially(SuiteRunner.java:437)
at org.testng.SuiteRunner.privateRun(SuiteRunner.java:397)
at org.testng.SuiteRunner.run(SuiteRunner.java:336)
at org.testng.SuiteRunnerWorker.runSuite(SuiteRunnerWorker.java:52)
at org.testng.SuiteRunnerWorker.run(SuiteRunnerWorker.java:95)
at org.testng.TestNG.runSuitesSequentially(TestNG.java:1280)
at org.testng.TestNG.runSuitesLocally(TestNG.java:1200)
at org.testng.TestNG.runSuites(TestNG.java:1114)
at org.testng.TestNG.run(TestNG.java:1082)
at org.testng.remote.AbstractRemoteTestNG.run(AbstractRemoteTestNG.java:115)
at org.testng.remote.RemoteTestNG.initAndRun(RemoteTestNG.java:251)
at org.testng.remote.RemoteTestNG.main(RemoteTestNG.java:77)
]]>
    </error>
  </testcase> <!-- test1 -->
</testsuite> <!-- com.testng.ExceptionTestNG -->
